[2025-01-15T12:19:17.118+0500] {local_task_job_runner.py:123} INFO - ::group::Pre task execution logs
[2025-01-15T12:19:17.130+0500] {taskinstance.py:2613} INFO - Dependencies all met for dep_context=non-requeueable deps ti=<TaskInstance: ForecastingPipeline.Task_ForecastingPipeline manual__2025-01-15T07:19:13.967662+00:00 [queued]>
[2025-01-15T12:19:17.137+0500] {taskinstance.py:2613} INFO - Dependencies all met for dep_context=requeueable deps ti=<TaskInstance: ForecastingPipeline.Task_ForecastingPipeline manual__2025-01-15T07:19:13.967662+00:00 [queued]>
[2025-01-15T12:19:17.137+0500] {taskinstance.py:2866} INFO - Starting attempt 1 of 2
[2025-01-15T12:19:17.149+0500] {taskinstance.py:2889} INFO - Executing <Task(PythonOperator): Task_ForecastingPipeline> on 2025-01-15 07:19:13.967662+00:00
[2025-01-15T12:19:17.156+0500] {standard_task_runner.py:72} INFO - Started process 36181 to run task
[2025-01-15T12:19:17.163+0500] {standard_task_runner.py:104} INFO - Running: ['airflow', 'tasks', 'run', 'ForecastingPipeline', 'Task_ForecastingPipeline', 'manual__2025-01-15T07:19:13.967662+00:00', '--job-id', '2', '--raw', '--subdir', 'DAGS_FOLDER/ForcastingPipeline.py', '--cfg-path', '/var/folders/j6/9x_46crd51ld6f4qmwpg0zgm0000gn/T/tmp0t4rtfbu']
[2025-01-15T12:19:17.167+0500] {standard_task_runner.py:105} INFO - Job 2: Subtask Task_ForecastingPipeline
[2025-01-15T12:19:17.213+0500] {task_command.py:467} INFO - Running <TaskInstance: ForecastingPipeline.Task_ForecastingPipeline manual__2025-01-15T07:19:13.967662+00:00 [running]> on host hamza-macbook-pro.local
[2025-01-15T12:19:17.273+0500] {taskinstance.py:3132} INFO - Exporting env vars: AIRFLOW_CTX_DAG_OWNER='airflow' AIRFLOW_CTX_DAG_ID='ForecastingPipeline' AIRFLOW_CTX_TASK_ID='Task_ForecastingPipeline' AIRFLOW_CTX_EXECUTION_DATE='2025-01-15T07:19:13.967662+00:00' AIRFLOW_CTX_TRY_NUMBER='1' AIRFLOW_CTX_DAG_RUN_ID='manual__2025-01-15T07:19:13.967662+00:00'
[2025-01-15T12:19:17.276+0500] {logging_mixin.py:190} INFO - Task instance is in running state
[2025-01-15T12:19:17.277+0500] {logging_mixin.py:190} INFO -  Previous state of the Task instance: queued
[2025-01-15T12:19:17.277+0500] {logging_mixin.py:190} INFO - Current task name:Task_ForecastingPipeline state:running start_date:2025-01-15 07:19:17.130413+00:00
[2025-01-15T12:19:17.278+0500] {logging_mixin.py:190} INFO - Dag name:ForecastingPipeline and current dag run status:running
[2025-01-15T12:19:17.279+0500] {taskinstance.py:731} INFO - ::endgroup::
[2025-01-15T12:19:17.326+0500] {ForcastingPipeline.py:35} ERROR - Pipeline script failed: /Users/mac/Desktop/Comapny2/CryptoPortfolioAI/.venv/bin/python: can't open file '/Users/mac/Desktop/Comapny2/CryptoPortfolioAI/PortfolioOptimizer/pipeline/pipeline.py': [Errno 2] No such file or directory

[2025-01-15T12:19:17.328+0500] {taskinstance.py:3311} ERROR - Task failed with exception
Traceback (most recent call last):
  File "/Users/mac/Desktop/Comapny2/CryptoPortfolioAI/.venv/lib/python3.10/site-packages/airflow/models/taskinstance.py", line 767, in _execute_task
    result = _execute_callable(context=context, **execute_callable_kwargs)
  File "/Users/mac/Desktop/Comapny2/CryptoPortfolioAI/.venv/lib/python3.10/site-packages/airflow/models/taskinstance.py", line 733, in _execute_callable
    return ExecutionCallableRunner(
  File "/Users/mac/Desktop/Comapny2/CryptoPortfolioAI/.venv/lib/python3.10/site-packages/airflow/utils/operator_helpers.py", line 252, in run
    return self.func(*args, **kwargs)
  File "/Users/mac/Desktop/Comapny2/CryptoPortfolioAI/.venv/lib/python3.10/site-packages/airflow/models/baseoperator.py", line 422, in wrapper
    return func(self, *args, **kwargs)
  File "/Users/mac/Desktop/Comapny2/CryptoPortfolioAI/.venv/lib/python3.10/site-packages/airflow/operators/python.py", line 238, in execute
    return_value = self.execute_callable()
  File "/Users/mac/Desktop/Comapny2/CryptoPortfolioAI/.venv/lib/python3.10/site-packages/airflow/operators/python.py", line 256, in execute_callable
    return runner.run(*self.op_args, **self.op_kwargs)
  File "/Users/mac/Desktop/Comapny2/CryptoPortfolioAI/.venv/lib/python3.10/site-packages/airflow/utils/operator_helpers.py", line 252, in run
    return self.func(*args, **kwargs)
  File "/Users/mac/Desktop/Comapny2/CryptoPortfolioAI/src/PortfolioOptimizer/DAGS/ForcastingPipeline.py", line 36, in run_pipeline
    raise e
  File "/Users/mac/Desktop/Comapny2/CryptoPortfolioAI/src/PortfolioOptimizer/DAGS/ForcastingPipeline.py", line 27, in run_pipeline
    result = subprocess.run(
  File "/Library/Frameworks/Python.framework/Versions/3.10/lib/python3.10/subprocess.py", line 526, in run
    raise CalledProcessError(retcode, process.args,
subprocess.CalledProcessError: Command '['python', 'PortfolioOptimizer/pipeline/pipeline.py']' returned non-zero exit status 2.
[2025-01-15T12:19:17.347+0500] {logging_mixin.py:190} INFO - Task instance in failure state
[2025-01-15T12:19:17.347+0500] {logging_mixin.py:190} INFO - Task start:2025-01-15 07:19:17.130413+00:00 end:2025-01-15 07:19:17.346441+00:00 duration:0.216028
[2025-01-15T12:19:17.348+0500] {logging_mixin.py:190} INFO - Task:<Task(PythonOperator): Task_ForecastingPipeline> dag:<DAG: ForecastingPipeline> dagrun:<DagRun ForecastingPipeline @ 2025-01-15 07:19:13.967662+00:00: manual__2025-01-15T07:19:13.967662+00:00, state:running, queued_at: 2025-01-15 07:19:13.999969+00:00. externally triggered: True>
[2025-01-15T12:19:17.349+0500] {logging_mixin.py:190} INFO - Failure caused by Command '['python', 'PortfolioOptimizer/pipeline/pipeline.py']' returned non-zero exit status 2.
[2025-01-15T12:19:17.349+0500] {taskinstance.py:1225} INFO - Marking task as UP_FOR_RETRY. dag_id=ForecastingPipeline, task_id=Task_ForecastingPipeline, run_id=manual__2025-01-15T07:19:13.967662+00:00, execution_date=20250115T071913, start_date=20250115T071917, end_date=20250115T071917
[2025-01-15T12:19:17.364+0500] {taskinstance.py:340} INFO - ::group::Post task execution logs
[2025-01-15T12:19:17.365+0500] {standard_task_runner.py:124} ERROR - Failed to execute job 2 for task Task_ForecastingPipeline (Command '['python', 'PortfolioOptimizer/pipeline/pipeline.py']' returned non-zero exit status 2.; 36181)
Traceback (most recent call last):
  File "/Users/mac/Desktop/Comapny2/CryptoPortfolioAI/.venv/lib/python3.10/site-packages/airflow/task/task_runner/standard_task_runner.py", line 117, in _start_by_fork
    ret = args.func(args, dag=self.dag)
  File "/Users/mac/Desktop/Comapny2/CryptoPortfolioAI/.venv/lib/python3.10/site-packages/airflow/cli/cli_config.py", line 49, in command
    return func(*args, **kwargs)
  File "/Users/mac/Desktop/Comapny2/CryptoPortfolioAI/.venv/lib/python3.10/site-packages/airflow/utils/cli.py", line 116, in wrapper
    return f(*args, **kwargs)
  File "/Users/mac/Desktop/Comapny2/CryptoPortfolioAI/.venv/lib/python3.10/site-packages/airflow/cli/commands/task_command.py", line 483, in task_run
    task_return_code = _run_task_by_selected_method(args, _dag, ti)
  File "/Users/mac/Desktop/Comapny2/CryptoPortfolioAI/.venv/lib/python3.10/site-packages/airflow/cli/commands/task_command.py", line 256, in _run_task_by_selected_method
    return _run_raw_task(args, ti)
  File "/Users/mac/Desktop/Comapny2/CryptoPortfolioAI/.venv/lib/python3.10/site-packages/airflow/cli/commands/task_command.py", line 341, in _run_raw_task
    return ti._run_raw_task(
  File "/Users/mac/Desktop/Comapny2/CryptoPortfolioAI/.venv/lib/python3.10/site-packages/airflow/utils/session.py", line 97, in wrapper
    return func(*args, session=session, **kwargs)
  File "/Users/mac/Desktop/Comapny2/CryptoPortfolioAI/.venv/lib/python3.10/site-packages/airflow/models/taskinstance.py", line 3005, in _run_raw_task
    return _run_raw_task(
  File "/Users/mac/Desktop/Comapny2/CryptoPortfolioAI/.venv/lib/python3.10/site-packages/airflow/models/taskinstance.py", line 273, in _run_raw_task
    TaskInstance._execute_task_with_callbacks(
  File "/Users/mac/Desktop/Comapny2/CryptoPortfolioAI/.venv/lib/python3.10/site-packages/airflow/models/taskinstance.py", line 3159, in _execute_task_with_callbacks
    result = self._execute_task(context, task_orig)
  File "/Users/mac/Desktop/Comapny2/CryptoPortfolioAI/.venv/lib/python3.10/site-packages/airflow/models/taskinstance.py", line 3183, in _execute_task
    return _execute_task(self, context, task_orig)
  File "/Users/mac/Desktop/Comapny2/CryptoPortfolioAI/.venv/lib/python3.10/site-packages/airflow/models/taskinstance.py", line 767, in _execute_task
    result = _execute_callable(context=context, **execute_callable_kwargs)
  File "/Users/mac/Desktop/Comapny2/CryptoPortfolioAI/.venv/lib/python3.10/site-packages/airflow/models/taskinstance.py", line 733, in _execute_callable
    return ExecutionCallableRunner(
  File "/Users/mac/Desktop/Comapny2/CryptoPortfolioAI/.venv/lib/python3.10/site-packages/airflow/utils/operator_helpers.py", line 252, in run
    return self.func(*args, **kwargs)
  File "/Users/mac/Desktop/Comapny2/CryptoPortfolioAI/.venv/lib/python3.10/site-packages/airflow/models/baseoperator.py", line 422, in wrapper
    return func(self, *args, **kwargs)
  File "/Users/mac/Desktop/Comapny2/CryptoPortfolioAI/.venv/lib/python3.10/site-packages/airflow/operators/python.py", line 238, in execute
    return_value = self.execute_callable()
  File "/Users/mac/Desktop/Comapny2/CryptoPortfolioAI/.venv/lib/python3.10/site-packages/airflow/operators/python.py", line 256, in execute_callable
    return runner.run(*self.op_args, **self.op_kwargs)
  File "/Users/mac/Desktop/Comapny2/CryptoPortfolioAI/.venv/lib/python3.10/site-packages/airflow/utils/operator_helpers.py", line 252, in run
    return self.func(*args, **kwargs)
  File "/Users/mac/Desktop/Comapny2/CryptoPortfolioAI/src/PortfolioOptimizer/DAGS/ForcastingPipeline.py", line 36, in run_pipeline
    raise e
  File "/Users/mac/Desktop/Comapny2/CryptoPortfolioAI/src/PortfolioOptimizer/DAGS/ForcastingPipeline.py", line 27, in run_pipeline
    result = subprocess.run(
  File "/Library/Frameworks/Python.framework/Versions/3.10/lib/python3.10/subprocess.py", line 526, in run
    raise CalledProcessError(retcode, process.args,
subprocess.CalledProcessError: Command '['python', 'PortfolioOptimizer/pipeline/pipeline.py']' returned non-zero exit status 2.
[2025-01-15T12:19:17.380+0500] {local_task_job_runner.py:266} INFO - Task exited with return code 1
[2025-01-15T12:19:17.400+0500] {taskinstance.py:3895} INFO - 0 downstream tasks scheduled from follow-on schedule check
[2025-01-15T12:19:17.401+0500] {local_task_job_runner.py:245} INFO - ::endgroup::
